{"name": "ootest_one2", "status": "failed", "statusDetails": {"message": "AssertionError: assert 1 == 3\n  +1\n  -3", "trace": "self = <testcase.test_one.Test_demo1 object at 0x000001CEFE644280>\n\n    @pytest.mark.run(order=1)\n    def ootest_one2(self):\n        print(\"第二个测试。。。\")\n>       assert 1 == 3\nE       assert 1 == 3\nE         +1\nE         -3\n\ntestcase\\test_one.py:20: AssertionError"}, "start": 1615635002373, "stop": 1615635002373, "uuid": "166cdd66-c68d-410d-9b1f-f9de5ab1a182", "historyId": "c72584dd4b4a256372e805ea78bcc529", "testCaseId": "ce0f39f23580e4c8ccb0b777c299a023", "fullName": "testcase.test_one.Test_demo1#ootest_one2", "labels": [{"name": "tag", "value": "run(order=1)"}, {"name": "parentSuite", "value": "testcase"}, {"name": "suite", "value": "test_one"}, {"name": "subSuite", "value": "Test_demo1"}, {"name": "host", "value": "DESKTOP-IMJPCQ7"}, {"name": "thread", "value": "22352-MainThread"}, {"name": "framework", "value": "pytest"}, {"name": "language", "value": "cpython3"}, {"name": "package", "value": "testcase.test_one"}]}